Workbook

Sheet Rent Insurance S - Consolidated
A1: Key | B1: Property | C1: Unit | D1: Resident | E1: Lease Start/Renewal Date | F1: Carrier | G1: Policy # | H1: Policy Start Date | I1: Expiration Date | J1: Status | K1: Reason | L1: Received | M1: Liability | N1: Last name | O1: Address
A2: =B2&"_"&C2 -> ATS_BG-300 | B2: ATS | C2: BG-300 | D2: Barnes, Viola Yvonne | E2: 45796 | F2: Assurant Liability | G2: RI 8495161 00 | H2: 45855 | I2: 46220 | J2: Active | L2: Yes | M2: 100000 | N2: Barnes | O2: =+INDEX('[1]Unit Setup View - Consolidated'!$AS:$AS,MATCH('Rent Insurance S - Consolidated'!$C2,'[1]Unit Setup View - Consolidated'!$AT:$AT,0)) -> 300 Brigade Court Ashland VA 23005
A3: =B3&"_"&C3 -> ATS_BG-302 | B3: ATS | C3: BG-302 | D3: Knightner, Monique Yvette | E3: 45786 | F3: Assurant Liability | G3: REN5506534 | H3: 45773 | I3: 46138 | J3: Active | L3: Yes | M3: 100000 | N3: Knightner | O3: =+INDEX('[1]Unit Setup View - Consolidated'!$AS:$AS,MATCH('Rent Insurance S - Consolidated'!$C3,'[1]Unit Setup View - Consolidated'!$AT:$AT,0)) -> 302 Brigade Court Ashland VA 23005
A4: =B4&"_"&C4 -> ATS_BG-304 | B4: ATS | C4: BG-304 | D4: Webber, Justin Michael | E4: 45737 | F4: eRenterPlan (LeasingDesk) | G4: 105050075 | H4: 45737 | I4: 46102 | J4: Active | L4: N/A | M4: 100000 | N4: Webber | O4: =+INDEX('[1]Unit Setup View - Consolidated'!$AS:$AS,MATCH('Rent Insurance S - Consolidated'!$C4,'[1]Unit Setup View - Consolidated'!$AT:$AT,0)) -> 304 Brigade Court Ashland VA 23005
A5: =B5&"_"&C5 -> ATS_BG-306 | B5: ATS | C5: BG-306 | D5: Sanderson, Donald Albert | E5: 45772 | F5: Geico | G5: REN 5501907 | H5: 45772 | I5: 46137 | J5: Active | L5: Yes | M5: 100000 | N5: Sanderson | O5: =+INDEX('[1]Unit Setup View - Consolidated'!$AS:$AS,MATCH('Rent Insurance S - Consolidated'!$C5,'[1]Unit Setup View - Consolidated'!$AT:$AT,0)) -> 306 Brigade Court Ashland VA 23005
A6: =B6&"_"&C6 -> ATS_BG-308 | B6: ATS | C6: BG-308 | D6: Mckinnon, Joshua | E6: 45797 | F6: Lemonade | G6: LP4ACAF8C88 | H6: 45914 | I6: 46279 | J6: Active | L6: Yes | M6: 100000 | N6: Mckinnon | O6: =+INDEX('[1]Unit Setup View - Consolidated'!$AS:$AS,MATCH('Rent Insurance S - Consolidated'!$C6,'[1]Unit Setup View - Consolidated'!$AT:$AT,0)) -> 308 Brigade Court Ashland VA 23005
A7: =B7&"_"&C7 -> ATS_BG-310 | B7: ATS | C7: BG-310 | D7: Capps, Lester | E7: 45775 | F7: Geico | G7: RIN 8427694 | H7: 45695 | I7: 46060 | J7: Active | L7: Yes | M7: 100000 | N7: Capps | O7: =+INDEX('[1]Unit Setup View - Consolidated'!$AS:$AS,MATCH('Rent Insurance S - Consolidated'!$C7,'[1]Unit Setup View - Consolidated'!$AT:$AT,0)) -> 310 Brigade Court Ashland VA 23005
A8: =B8&"_"&C8 -> ATS_BG-312 | B8: ATS | C8: BG-312 | D8: Rincon, Rhonny | E8: 45901 | F8: Progressive Insurance Company | G8: VAA281812 | H8: 45859 | I8: 46224 | J8: Active | L8: Yes | M8: 100000 | N8: Rincon | O8: =+INDEX('[1]Unit Setup View - Consolidated'!$AS:$AS,MATCH('Rent Insurance S - Consolidated'!$C8,'[1]Unit Setup View - Consolidated'!$AT:$AT,0)) -> 312 Brigade Court Ashland VA 23005
A9: =B9&"_"&C9 -> ATS_BG-314 | B9: ATS | C9: BG-314 | D9: Jones, Allen | E9: 45717 | F9: eRenterPlan (LeasingDesk) | G9: 102536980 | H9: 44590 | I9: 46051 | J9: Active | L9: N/A | M9: 100000 | N9: Jones | O9: =+INDEX('[1]Unit Setup View - Consolidated'!$AS:$AS,MATCH('Rent Insurance S - Consolidated'!$C9,'[1]Unit Setup View - Consolidated'!$AT:$AT,0)) -> 314 Brigade Court Ashland VA 23005
A10: =B10&"_"&C10 -> ATS_BG-316 | B10: ATS | C10: BG-316 | D10: klassen, aaron Frank | E10: 45966 | F10: eRenterPlan (LeasingDesk) | G10: 105567256 | H10: 45965 | I10: 46330 | J10: Active | L10: N/A | M10: 100000 | N10: klassen | O10: =+INDEX('[1]Unit Setup View - Consolidated'!$AS:$AS,MATCH('Rent Insurance S - Consolidated'!$C10,'[1]Unit Setup View - Consolidated'!$AT:$AT,0)) -> 316 Brigade Court Ashland VA 23005
A11: =B11&"_"&C11 -> ATS_BG-318 | B11: ATS | C11: BG-318 | D11: Holmes, Nicole | E11: 45627 | F11: Travelers Insurance Company | G11: 6160330026341 | H11: 45476 | I11: 45841 | J11: Cancelled | L11: Yes | M11: 100000 | N11: Holmes | O11: =+INDEX('[1]Unit Setup View - Consolidated'!$AS:$AS,MATCH('Rent Insurance S - Consolidated'!$C11,'[1]Unit Setup View - Consolidated'!$AT:$AT,0)) -> 318 Brigade Court Ashland VA 23005
A12: =B12&"_"&C12 -> ATS_BG-320 | B12: ATS | C12: BG-320 | D12: Salazar, Emelin Yuliana | E12: 45782 | F12: Trisura Ins Company | G12: 89720665 | H12: 45782 | I12: 46147 | J12: Active | L12: Yes | M12: 100000 | N12: Salazar | O12: =+INDEX('[1]Unit Setup View - Consolidated'!$AS:$AS,MATCH('Rent Insurance S - Consolidated'!$C12,'[1]Unit Setup View - Consolidated'!$AT:$AT,0)) -> 320 Brigade Court Ashland VA 23005
A13: =B13&"_"&C13 -> ATS_BG-322 | B13: ATS | C13: BG-322 | D13: Levy, Christopher Ryan | E13: 45810 | F13: Trisura Ins Company | G13: 89942370 | H13: 45806 | I13: 46171 | J13: Active | L13: Yes | M13: 100000 | N13: Levy | O13: =+INDEX('[1]Unit Setup View - Consolidated'!$AS:$AS,MATCH('Rent Insurance S - Consolidated'!$C13,'[1]Unit Setup View - Consolidated'!$AT:$AT,0)) -> 322 Brigade Court Ashland VA 23005
A14: =B14&"_"&C14 -> ATS_BG-324 | B14: ATS | C14: BG-324 | D14: Estrada Garcia, Joe Angel Francisco | E14: 45793 | F14: eRenterPlan (LeasingDesk) | G14: 105172266 | H14: 45793 | I14: 46158 | J14: active | L14: N/A | M14: 100000 | N14: Estrada Garcia | O14: =+INDEX('[1]Unit Setup View - Consolidated'!$AS:$AS,MATCH('Rent Insurance S - Consolidated'!$C14,'[1]Unit Setup View - Consolidated'!$AT:$AT,0)) -> 324 Brigade Court Ashland VA 23005
A15: =B15&"_"&C15 -> ATS_BG-326 | B15: ATS | C15: BG-326 | D15: Gray, Douglas Allen | E15: 45860 | F15: eRenterPlan (LeasingDesk) | G15: 105331498 | H15: 45856 | I15: 46221 | J15: Active | L15: N/A | M15: 100000 | N15: Gray | O15: =+INDEX('[1]Unit Setup View - Consolidated'!$AS:$AS,MATCH('Rent Insurance S - Consolidated'!$C15,'[1]Unit Setup View - Consolidated'!$AT:$AT,0)) -> 326 Brigade Court Ashland VA 23005
A16: =B16&"_"&C16 -> ATS_BG-328 | B16: ATS | C16: BG-328 | J16: Vacant | L16: No | O16: =+INDEX('[1]Unit Setup View - Consolidated'!$AS:$AS,MATCH('Rent Insurance S - Consolidated'!$C16,'[1]Unit Setup View - Consolidated'!$AT:$AT,0)) -> 328 Brigade Court Ashland VA 23005
A17: =B17&"_"&C17 -> ATS_BP-100 | B17: ATS | C17: BP-100 | D17: Ferguson, Brian | E17: 45841 | F17: Safeco | G17: OF2996089 | H17: 45700 | I17: 46065 | J17: Active | L17: Yes | M17: 100000 | N17: Ferguson | O17: =+INDEX('[1]Unit Setup View - Consolidated'!$AS:$AS,MATCH('Rent Insurance S - Consolidated'!$C17,'[1]Unit Setup View - Consolidated'!$AT:$AT,0)) -> 100 Bruton Parrish Ashland VA 23005
A18: =B18&"_"&C18 -> ATS_BP-101 | B18: ATS | C18: BP-101 | J18: Vacant | L18: No | O18: =+INDEX('[1]Unit Setup View - Consolidated'!$AS:$AS,MATCH('Rent Insurance S - Consolidated'!$C18,'[1]Unit Setup View - Consolidated'!$AT:$AT,0)) -> 101 Bruton Parrish Ashland VA 23005
A19: =B19&"_"&C19 -> ATS_BP-102 | B19: ATS | C19: BP-102 | D19: Quick, Leon | E19: 45930 | F19: Nationwide | G19: 5345HS000961 | H19: 45922 | I19: 46287 | J19: Active | L19: Yes | M19: 100000 | N19: Quick | O19: =+INDEX('[1]Unit Setup View - Consolidated'!$AS:$AS,MATCH('Rent Insurance S - Consolidated'!$C19,'[1]Unit Setup View - Consolidated'!$AT:$AT,0)) -> 102 Bruton Parrish Ashland VA 23005
A20: =B20&"_"&C20 -> ATS_BP-103 | B20: ATS | C20: BP-103 | D20: Grim, Jonathan | E20: 45857 | F20: Homebody | G20: RTH11467668 | H20: 44390 | I20: 46219 | J20: Active | L20: Yes | M20: 100000 | N20: Grim | O20: =+INDEX('[1]Unit Setup View - Consolidated'!$AS:$AS,MATCH('Rent Insurance S - Consolidated'!$C20,'[1]Unit Setup View - Consolidated'!$AT:$AT,0)) -> 103 Bruton Parrish Ashland VA 23005
A21: =B21&"_"&C21 -> ATS_BP-104 | B21: ATS | C21: BP-104 | D21: Mccrea, Katherine | E21: 45962 | F21: Liberty Mutual | G21: H4J2312611167541 | H21: 45598 | I21: 45963 | J21: Cancelled | L21: Yes | M21: 100000 | N21: Mccrea | O21: =+INDEX('[1]Unit Setup View - Consolidated'!$AS:$AS,MATCH('Rent Insurance S - Consolidated'!$C21,'[1]Unit Setup View - Consolidated'!$AT:$AT,0)) -> 104 Bruton Parrish Ashland VA 23005
A22: =B22&"_"&C22 -> ATS_BP-105 | B22: ATS | C22: BP-105 | D22: Ward, Jacob Thomas | E22: 45737 | F22: TheGuarantors | G22: 89247741 | H22: 45737 | I22: 46102 | J22: Active | L22: Yes | M22: 100000 | N22: Ward | O22: =+INDEX('[1]Unit Setup View - Consolidated'!$AS:$AS,MATCH('Rent Insurance S - Consolidated'!$C22,'[1]Unit Setup View - Consolidated'!$AT:$AT,0)) -> 105 Bruton Parrish Ashland VA 23005
A23: =B23&"_"&C23 -> ATS_BP-106 | B23: ATS | C23: BP-106 | D23: Hubbard, Marcus | E23: 45658 | F23: eRenterPlan (LeasingDesk) | G23: 102524697 | H23: 44586 | I23: 46047 | J23: Active | L23: N/A | M23: 100000 | N23: Hubbard | O23: =+INDEX('[1]Unit Setup View - Consolidated'!$AS:$AS,MATCH('Rent Insurance S - Consolidated'!$C23,'[1]Unit Setup View - Consolidated'!$AT:$AT,0)) -> 106 Bruton Parrish Ashland VA 23005
A24: =B24&"_"&C24 -> ATS_BP-107 | B24: ATS | C24: BP-107 | D24: Marrin, Colin Patrick | E24: 45723 | F24: USAA Insurance Company | G24: CIC-029402293 REN001 | H24: 45721 | I24: 46087 | J24: Active | L24: Yes | M24: 100000 | N24: Marrin | O24: =+INDEX('[1]Unit Setup View - Consolidated'!$AS:$AS,MATCH('Rent Insurance S - Consolidated'!$C24,'[1]Unit Setup View - Consolidated'!$AT:$AT,0)) -> 107 Bruton Parrish Ashland VA 23005
A25: =B25&"_"&C25 -> ATS_BP-108 | B25: ATS | C25: BP-108 | J25: Vacant | L25: No | O25: =+INDEX('[1]Unit Setup View - Consolidated'!$AS:$AS,MATCH('Rent Insurance S - Consolidated'!$C25,'[1]Unit Setup View - Consolidated'!$AT:$AT,0)) -> 108 Bruton Parrish Ashland VA 23005
A26: =B26&"_"&C26 -> ATS_BP-109 | B26: ATS | C26: BP-109 | J26: Vacant | L26: No | O26: =+INDEX('[1]Unit Setup View - Consolidated'!$AS:$AS,MATCH('Rent Insurance S - Consolidated'!$C26,'[1]Unit Setup View - Consolidated'!$AT:$AT,0)) -> 109 Bruton Parrish Ashland VA 23005
A27: =B27&"_"&C27 -> ATS_BP-110 | B27: ATS | C27: BP-110 | D27: Hinton, Jamie J | E27: 45639 | F27: eRenterPlan (LeasingDesk) | G27: 104854847 | H27: 45637 | I27: 46002 | J27: Active | L27: N/A | M27: 100000 | N27: Hinton | O27: =+INDEX('[1]Unit Setup View - Consolidated'!$AS:$AS,MATCH('Rent Insurance S - Consolidated'!$C27,'[1]Unit Setup View - Consolidated'!$AT:$AT,0)) -> 110 Bruton Parrish Ashland VA 23005
A28: =B28&"_"&C28 -> ATS_BP-111 | B28: ATS | C28: BP-111 | D28: Gibson, Richard | E28: 45901 | F28: State Farm Insurance | G28: 46C7N7869 | H28: 45527 | I28: 45892 | J28: Cancelled | L28: Yes | M28: 100000 | N28: Gibson | O28: =+INDEX('[1]Unit Setup View - Consolidated'!$AS:$AS,MATCH('Rent Insurance S - Consolidated'!$C28,'[1]Unit Setup View - Consolidated'!$AT:$AT,0)) -> 111 Bruton Parrish Ashland VA 23005
A29: =B29&"_"&C29 -> ATS_BP-112 | B29: ATS | C29: BP-112 | D29: Henry, Dayjuan Elian | E29: 45932 | F29: eRenterPlan (LeasingDesk) | G29: 105504685 | H29: 45932 | I29: 45966 | J29: Cancelled | K29: Due to Non-payment | L29: N/A | M29: 100000 | N29: Henry | O29: =+INDEX('[1]Unit Setup View - Consolidated'!$AS:$AS,MATCH('Rent Insurance S - Consolidated'!$C29,'[1]Unit Setup View - Consolidated'!$AT:$AT,0)) -> 112 Bruton Parrish Ashland VA 23005
A30: =B30&"_"&C30 -> ATS_BP-113 | B30: ATS | C30: BP-113 | D30: sousa, Cleiton | E30: 45804 | J30: Override | K30: By TFITZGERALD1 - 04/18/2023 : Will Provide asap. | L30: No | N30: sousa | O30: =+INDEX('[1]Unit Setup View - Consolidated'!$AS:$AS,MATCH('Rent Insurance S - Consolidated'!$C30,'[1]Unit Setup View - Consolidated'!$AT:$AT,0)) -> 113 Bruton Parrish Ashland VA 23005
A31: =B31&"_"&C31 -> ATS_BP-114 | B31: ATS | C31: BP-114 | D31: Davis, Debora Santia | E31: 45595 | F31: eRenterPlan (LeasingDesk) | G31: 104761896 | H31: 45595 | I31: 45962 | J31: Cancelled | K31: Due to Non-payment | L31: N/A | M31: 100000 | N31: Davis | O31: =+INDEX('[1]Unit Setup View - Consolidated'!$AS:$AS,MATCH('Rent Insurance S - Consolidated'!$C31,'[1]Unit Setup View - Consolidated'!$AT:$AT,0)) -> 114 Bruton Parrish Ashland VA 23005
A32: =B32&"_"&C32 -> ATS_BP-115 | B32: ATS | C32: BP-115 | D32: Jaffe, Angela Rebecca | E32: 45673 | F32: Central Mutual Ins. Company | G32: FMH3433628 | H32: 45813 | I32: 46178 | J32: Active | L32: Yes | M32: 100000 | N32: Jaffe | O32: =+INDEX('[1]Unit Setup View - Consolidated'!$AS:$AS,MATCH('Rent Insurance S - Consolidated'!$C32,'[1]Unit Setup View - Consolidated'!$AT:$AT,0)) -> 115 Bruton Parrish Ashland VA 23005
A33: =B33&"_"&C33 -> ATS_BP-116 | B33: ATS | C33: BP-116 | D33: Joseph, Paula Nezra | E33: 45839 | F33: Allstate Insurance | G33: 818823857 | H33: 45839 | I33: 46204 | J33: Active | L33: Yes | M33: 100000 | N33: Joseph | O33: =+INDEX('[1]Unit Setup View - Consolidated'!$AS:$AS,MATCH('Rent Insurance S - Consolidated'!$C33,'[1]Unit Setup View - Consolidated'!$AT:$AT,0)) -> 116 Bruton Parrish Ashland VA 23005
A34: =B34&"_"&C34 -> ATS_BP-117 | B34: ATS | C34: BP-117 | D34: Jones, Richard | E34: 45944 | F34: Geico | G34: REN5970572 | H34: 45944 | I34: 46309 | J34: Active | L34: Yes | M34: 100000 | N34: Jones | O34: =+INDEX('[1]Unit Setup View - Consolidated'!$AS:$AS,MATCH('Rent Insurance S - Consolidated'!$C34,'[1]Unit Setup View - Consolidated'!$AT:$AT,0)) -> 117 Bruton Parrish Ashland VA 23005
A35: =B35&"_"&C35 -> ATS_BP-118 | B35: ATS | C35: BP-118 | D35: Argueta, Aryani Mixue | E35: 45944 | J35: Override | K35: By TFITZGERALD1 - 09/26/2023 : Sending new policy | L35: No | N35: Argueta | O35: =+INDEX('[1]Unit Setup View - Consolidated'!$AS:$AS,MATCH('Rent Insurance S - Consolidated'!$C35,'[1]Unit Setup View - Consolidated'!$AT:$AT,0)) -> 118 Bruton Parrish Ashland VA 23005
A36: =B36&"_"&C36 -> ATS_BP-119 | B36: ATS | C36: BP-119 | J36: Vacant | L36: No | O36: =+INDEX('[1]Unit Setup View - Consolidated'!$AS:$AS,MATCH('Rent Insurance S - Consolidated'!$C36,'[1]Unit Setup View - Consolidated'!$AT:$AT,0)) -> 119 Bruton Parrish Ashland VA 23005
A37: =B37&"_"&C37 -> ATS_BP-121 | B37: ATS | C37: BP-121 | D37: Ezer, Mehmet | E37: 45839 | F37: Geico | G37: 4674009 | H37: 45837 | I37: 46202 | J37: Active | L37: Yes | M37: 100000 | N37: Ezer | O37: =+INDEX('[1]Unit Setup View - Consolidated'!$AS:$AS,MATCH('Rent Insurance S - Consolidated'!$C37,'[1]Unit Setup View - Consolidated'!$AT:$AT,0)) -> 121 Bruton Parrish Ashland VA 23005
A38: =B38&"_"&C38 -> ATS_BP-123 | B38: ATS | C38: BP-123 | D38: Pendleton, Alex Maurice | E38: 45703 | F38: eRenterPlan (LeasingDesk) | G38: 103397586 | H38: 45030 | I38: 46126 | J38: Active | L38: N/A | M38: 100000 | N38: Pendleton | O38: =+INDEX('[1]Unit Setup View - Consolidated'!$AS:$AS,MATCH('Rent Insurance S - Consolidated'!$C38,'[1]Unit Setup View - Consolidated'!$AT:$AT,0)) -> 123 Bruton Parrish Ashland VA 23005
A39: =B39&"_"&C39 -> ATS_CW-400 | B39: ATS | C39: CW-400 | D39: Eskridge, Sarah | E39: 45757 | F39: State Farm Insurance | G39: 46-GE-S186-3 | H39: 45757 | I39: 46122 | J39: Active | L39: Yes | M39: 300000 | N39: Eskridge | O39: =+INDEX('[1]Unit Setup View - Consolidated'!$AS:$AS,MATCH('Rent Insurance S - Consolidated'!$C39,'[1]Unit Setup View - Consolidated'!$AT:$AT,0)) -> 400 Cornwallis Court Ashland VA 23005
A40: =B40&"_"&C40 -> ATS_CW-401 | B40: ATS | C40: CW-401 | D40: Wallace, Raven | E40: 45805 | F40: Liberty Mutual | G40: H4J23195384145 | H40: 45805 | I40: 46170 | J40: Active | L40: Yes | M40: 100000 | N40: Wallace | O40: =+INDEX('[1]Unit Setup View - Consolidated'!$AS:$AS,MATCH('Rent Insurance S - Consolidated'!$C40,'[1]Unit Setup View - Consolidated'!$AT:$AT,0)) -> 401 Cornwallis Court Ashland VA 23005
...
